Workbook

Sheet Overview
E1: Model My Watershed BMP Spreadsheet Tool
E2: Load Reductions from BMP Implementation in Urban and Rural Areas
B4: Version: | C4: 2022-07-05 at 1:30am ET
B6: Developed by: | C6: Barry Evans, Drexel University & Penn State University
C7: Anthony Aufdenkampe, LimnoTech
C8: Mike Hickman, Center for Watershed Protection
C9: Reid Christianson, Center for Watershed Protection & University of Illinois
B11: Repository & Archives: | C11: https://github.com/WikiWatershed/MMW-BMP-spreadsheet-tool
B12: Latest Version: | C12: https://raw.githubusercontent.com/WikiWatershed/MMW-BMP-spreadsheet-tool/master/MMW_BMP_Spreadsheet_Tool.xlsx.
B13: User Manual: | C13: https://raw.githubusercontent.com/WikiWatershed/MMW-BMP-spreadsheet-tool/master/docs/MMW_BMP_Spreadsheet_Tool_UserManual.docx
A15: OVERVIEW:
A16: This tool provides the ability to use results from a Model My Watershed "multi-year" model run for the purpose of estimating loading rates for different "source areas", and then subsequently calculating potential load reductions that might result from the implementation of both urban and agricultural BMPs in a given watershed.
A17: The tool is based on the concept of "composite" loading rates whereby both "upland" and "streambank-eroded" loads are combined to facilitate the estimation of load reductions based on the use of various BMPs as applied to different developed land and agricultural land categories.
A19: THIS TOOL INCLUDES:
A20: Section 2 (Loading Rate Look-Up Tables) contains the Look-Up Tables for different sources that incorporate Land Use (upland source), Stream Bank (erosion) and Farm Animal Loads. The "Total" (pollutant) Loading Rate values in these Tables are used to calculate Baseline and Existing loads as well as "future" loads from proposed urban and agricultural BMP load reductions.
A21: * In the MMW model run, Stream Bank and Farm Animal loads are modeled as separate sources/outputs, and therefore must be apportioned into the land use loads. This calculation has been completed herein and the results are summarized on the Look-up Table. Stream Bank loads are mostly attributable to developed lands. Farm Animal loads are attributed to Cropland and Hay/Pasture land uses.
A22: * The Look-Up Tables also show loads calculated by the MMW model from septic, groundwater and point sources. However, per PA DEP guidance, these loads are NOT included in the land use loading rates presented in the Table. These loads are not loads that enter the MS4 and therefore these loads are not a pollutant load that is required to be addressed in the MS4 program. Please note, when comparing the nitrogen and phosphorus loading rates to other literature values for a watershed, the rates in this workbook may appear lower by land use for nutrients because of these adjustments. However, since groundwater loads of nitrogen and phosphorus are generally attributed to long-term agricultural practices, load reductions for this source can be simulated using the "Nutrient Management" option found in the "Agricultural BMPs" tab.
A23: Section 3 (MMW Output) contains results from the MMW output file that are used for calculations throughout this workbook.
A24: Sections 4 to 7 Contain supporting documentation that show how the calculations were performed to arrive at the values for the watershed that were presented in the Look-up Table in Section 2.
B26: Tabs that require or allow user input
B27: These tabs contain calculated values or provide descriptive information. No user input is required.
B28: Final results tab.
A30: Detailed Instructions are provided in a user manual that can be obtained at the following link: | I30: https://raw.githubusercontent.com/WikiWatershed/MMW-BMP-spreadsheet-tool/master/docs/MMW_BMP_Spreadsheet_Tool_UserManual.docx
A32: LIMITATIONS:
A33: This Excel workbook tool was originally developed for use by municipalities that have MS4 discharges and load reduction responsibilities in Pennsylvania. This tool calculates land use pollutant loading rates for TSS, TN and TP using calculations, methodology, assumptions, and data based on, and consistent with, the MapShed model used in PA, and is also consistent with PADEP’s 2017 TMDL and PRP instructions for MS4s. Now that the modeling routines in MapShed have been incorporated into Model My Watershed, this tool can also utilize output from a MMW run for a given watershed. Similarly, it can be used in other geographic areas where similar load reduction estimates have to be made.

Sheet TechDocs
A1: Impervious Fraction LUT
B2: The percent impervious surface estimates for different types of developed land are based on those used in the original MapShed modelling application, and it is recommended that they not be changed when using this tool. However, they can be overridden using the look-up table provided below.
B4: Source | C4: MapShed default Impervious (fraction) | D4: Manual Entry Impervious (fraction) | E4: Impervious (fraction) to use
B5: Source | C5: impervFraction_defaultMapShed | D5: impervFraction_manualEntry | E5: impervFraction_toUse
B6: Hay/Past | E6: =IF(ISNUMBER(Impervious[[#This Row],[impervFraction_manualEntry]]),Impervious[[#This Row],[impervFraction_manualEntry]],Impervious[[#This Row],[impervFraction_defaultMapShed]]) -> 0
B7: Cropland | E7: =IF(ISNUMBER(Impervious[[#This Row],[impervFraction_manualEntry]]),Impervious[[#This Row],[impervFraction_manualEntry]],Impervious[[#This Row],[impervFraction_defaultMapShed]]) -> 0
B8: Forest | E8: =IF(ISNUMBER(Impervious[[#This Row],[impervFraction_manualEntry]]),Impervious[[#This Row],[impervFraction_manualEntry]],Impervious[[#This Row],[impervFraction_defaultMapShed]]) -> 0
B9: Wetland | E9: =IF(ISNUMBER(Impervious[[#This Row],[impervFraction_manualEntry]]),Impervious[[#This Row],[impervFraction_manualEntry]],Impervious[[#This Row],[impervFraction_defaultMapShed]]) -> 0
B10: Disturbed | E10: =IF(ISNUMBER(Impervious[[#This Row],[impervFraction_manualEntry]]),Impervious[[#This Row],[impervFraction_manualEntry]],Impervious[[#This Row],[impervFraction_defaultMapShed]]) -> 0
B11: Turfgrass | E11: =IF(ISNUMBER(Impervious[[#This Row],[impervFraction_manualEntry]]),Impervious[[#This Row],[impervFraction_manualEntry]],Impervious[[#This Row],[impervFraction_defaultMapShed]]) -> 0
B12: Open_Land | E12: =IF(ISNUMBER(Impervious[[#This Row],[impervFraction_manualEntry]]),Impervious[[#This Row],[impervFraction_manualEntry]],Impervious[[#This Row],[impervFraction_defaultMapShed]]) -> 0
B13: Bare_Rock | E13: =IF(ISNUMBER(Impervious[[#This Row],[impervFraction_manualEntry]]),Impervious[[#This Row],[impervFraction_manualEntry]],Impervious[[#This Row],[impervFraction_defaultMapShed]]) -> 0
B14: Sandy_Areas | E14: =IF(ISNUMBER(Impervious[[#This Row],[impervFraction_manualEntry]]),Impervious[[#This Row],[impervFraction_manualEntry]],Impervious[[#This Row],[impervFraction_defaultMapShed]]) -> 0
B15: Unpaved_Road | E15: =IF(ISNUMBER(Impervious[[#This Row],[impervFraction_manualEntry]]),Impervious[[#This Row],[impervFraction_manualEntry]],Impervious[[#This Row],[impervFraction_defaultMapShed]]) -> 0
B16: Ld_Mixed | C16: 0.15 | E16: =IF(ISNUMBER(Impervious[[#This Row],[impervFraction_manualEntry]]),Impervious[[#This Row],[impervFraction_manualEntry]],Impervious[[#This Row],[impervFraction_defaultMapShed]]) -> 0.15
B17: Md_Mixed | C17: 0.52 | E17: =IF(ISNUMBER(Impervious[[#This Row],[impervFraction_manualEntry]]),Impervious[[#This Row],[impervFraction_manualEntry]],Impervious[[#This Row],[impervFraction_defaultMapShed]]) -> 0.52
B18: Hd_Mixed | C18: 0.87 | E18: =IF(ISNUMBER(Impervious[[#This Row],[impervFraction_manualEntry]]),Impervious[[#This Row],[impervFraction_manualEntry]],Impervious[[#This Row],[impervFraction_defaultMapShed]]) -> 0.87
B19: Ld_Residential | C19: 0.15 | E19: =IF(ISNUMBER(Impervious[[#This Row],[impervFraction_manualEntry]]),Impervious[[#This Row],[impervFraction_manualEntry]],Impervious[[#This Row],[impervFraction_defaultMapShed]]) -> 0.15
B20: Md_Residential | C20: 0.52 | E20: =IF(ISNUMBER(Impervious[[#This Row],[impervFraction_manualEntry]]),Impervious[[#This Row],[impervFraction_manualEntry]],Impervious[[#This Row],[impervFraction_defaultMapShed]]) -> 0.52
B21: Hd_Residential | C21: 0.87 | E21: =IF(ISNUMBER(Impervious[[#This Row],[impervFraction_manualEntry]]),Impervious[[#This Row],[impervFraction_manualEntry]],Impervious[[#This Row],[impervFraction_defaultMapShed]]) -> 0.87
B22: Ld_Mixed - Upland | C22: 0.15 | E22: =IF(ISNUMBER(Impervious[[#This Row],[impervFraction_manualEntry]]),Impervious[[#This Row],[impervFraction_manualEntry]],Impervious[[#This Row],[impervFraction_defaultMapShed]]) -> 0.15
B23: Md_Mixed - Upland | C23: 0.52 | E23: =IF(ISNUMBER(Impervious[[#This Row],[impervFraction_manualEntry]]),Impervious[[#This Row],[impervFraction_manualEntry]],Impervious[[#This Row],[impervFraction_defaultMapShed]]) -> 0.52
B24: Hd_Mixed - Upland | C24: 0.87 | E24: =IF(ISNUMBER(Impervious[[#This Row],[impervFraction_manualEntry]]),Impervious[[#This Row],[impervFraction_manualEntry]],Impervious[[#This Row],[impervFraction_defaultMapShed]]) -> 0.87
B25: Ld_Residential - Upland | C25: 0.15 | E25: =IF(ISNUMBER(Impervious[[#This Row],[impervFraction_manualEntry]]),Impervious[[#This Row],[impervFraction_manualEntry]],Impervious[[#This Row],[impervFraction_defaultMapShed]]) -> 0.15
B26: Md_Residential - Upland | C26: 0.52 | E26: =IF(ISNUMBER(Impervious[[#This Row],[impervFraction_manualEntry]]),Impervious[[#This Row],[impervFraction_manualEntry]],Impervious[[#This Row],[impervFraction_defaultMapShed]]) -> 0.52
B27: Hd_Residential - Upland | C27: 0.87 | E27: =IF(ISNUMBER(Impervious[[#This Row],[impervFraction_manualEntry]]),Impervious[[#This Row],[impervFraction_manualEntry]],Impervious[[#This Row],[impervFraction_defaultMapShed]]) -> 0.87
B29: BMP Load and Efficiencies used in the Load Reduction Calculations (DO NOT ALTER):
B30: Street Sweeping | C30: TSS Reduction (%) | D30: TP Reduction (%) | E30: TN Reduction (%) | F30: Road Width (ft)
B31: Average of SCP1 - SCP11 | C31: =0.0715 -> 0.0715 | D31: =0.0345 -> 0.0345 | E31: =0.0125 -> 0.0125 | F31: 20
B33: Stream Restoration - Protocol 1 | C33: TSS (lbs/ft/yr) | D33: TP (lbs/ft/yr) | E33: TN (lbs/ft/yr)
B34: Default | C34: 115 | D34: 0.174 | E34: 0.192
B35: Calculated | C35: =+'MMW Output'!N18 -> 154.14682 | D35: =+'MMW Output'!O18 -> 0.095971988 | E35: =+'MMW Output'!P18 -> 0.038368427
B36: Minimum | C36: =MIN(C34,C35) -> 115 | D36: =MIN(D34,D35) -> 0.095971988 | E36: =MIN(E34,E35) -> 0.038368427
A39: PERFORMANCE STANDARD APPROACH for use with urban BMPs (as referenced in PA DEP permit materials; original source citation at bottom of page.)
A40: MUNICIPALITY: For the BMP of choice, consult the Expert Panel Table below and Report cited below to determine if the BMP is an RR, ST or Other type of practice.
A41: The type of practice, runoff reduction versus stormwater treatment, is calculated differently with different efficiency curves.
A80: Source: | B80: https://www.chesapeakebay.net/documents/Final-CBP-Approved-Expert-Panel-Report-on-Stormwater-Performance-Standards-LONG_012015.pdf
A81: Recommendations of the Expert Panel to Define Removal Rates for New State Stormwater Performance Standards
A82: Stewart Comstock, Scott Crafton, Randy Greer, Peter Hill, Dave Hirschman, Shoreh Karimpour, Ken Murin, Jennifer Orr, Fred Rose, Sherry Wilkins
A83: Revised: January 20, 2015
...

Sheet MMW Output
A1: Look-Up Table for MMW Land Use Loading Rates
A2: Watershed: | B2: =+C13 -> User Specified
A3: Year: | B3: =+C14 -> User Specified
A5: Section 3: | B5: MMW Model Output
A7: This page is where the output data from a multi-year MMW model run is to be copied and pasted into this workbook (either manually or automatically) and is the source data for calculations throughout the workbook. 1. Source File Name - User-specified filename for the output file from MMW (optional). 2. Watershed Name - User-specified name of a watershed for which land use loading rates are being calculated (optional). 3. Source file - The annual pollutant load and area data, in Metric Units, is copied directly from the MMW output file into the different locations highlighted in GREEN below and subsequently converted to English Units to the columns highlighted in BLUE below. 4. Year - the year modeled (optional).
B10: Data Entered By: | C10: User Specified
B11: Date Data Entered: | C11: User Specified
B12: Source File Name: | C12: User Specified
B13: Watershed: | C13: User Specified
B14: Year: | C14: User Specified
C16: Model My Watershed OUTPUT DATA | K16: STREAM LENGTHS* | L16: KM* | M16: FEET
N17: Sed lb/ft | O17: TN lb/ft | P17: TP lb/ft
A18: Source | C18: Area | D18: Sediment | E18: Tot N | F18: Tot P | K18: Total Length | L18: 105.59 | M18: =L18*3280.84 -> 346423.9 | N18: =(D38*2000)/M18 -> 154.14682 | O18: =E38/M18 -> 0.095971988 | P18: =F38/M18 -> 0.038368427
A19: Units | C19: acres | D19: tons/year | E19: lbs/year | F19: lbs/year | K19: Ag Streams | L19: 1.67 | M19: =L19*3280.84 -> 5479.0028
A20: Hay/Past | C20: =F60 -> 1666.6667 | D20: =N48 -> 136.61541 | E20: =O48 -> 1861.461 | F20: =P48 -> 687.519 | K20: Non-Ag Streams | L20: 103.91 | M20: =L20*3280.84 -> 340912.08
A21: Cropland | C21: =F61 -> 491.35802 | D21: =N49 -> 316.40659 | E21: =O49 -> 3203.424 | F21: =P49 -> 838.1205
A22: Forest | C22: =SUM(F55:F57)+F58 -> 9730.8642 | D22: =N50 -> 7.9434023 | E22: =O50 -> 1136.898 | F22: =P50 -> 73.647 | K22: * These values can be obtained from the "Stream" tab in the "Analyze" section of a Model My Watershed run
A23: Wetland | C23: =F62+F63 -> 656.79012 | D23: =N51 -> 0.7252245 | E23: =O51 -> 254.457 | F23: =P51 -> 14.553
A24: Disturbed | C24: 0 | D24: 0 | E24: 0 | F24: 0 | K24: FARM ANIMAL DATA
A25: Turfgrass | C25: 0 | D25: 0 | E25: 0 | F25: 0
A26: Open_Land | C26: =F59 -> 66.666667 | D26: =N52 -> 1.7845065 | E26: =O52 -> 67.6935 | F26: =P52 -> 4.6305 | K26: TYPE* | L26: NUMBER* | M26: AVG WT KG | N26: TOTAL KG | O26: TOTAL AEU | P26: KG N/AEU/DAY | Q26: KG P/AEU/DAY | R26: TOTAL N/DAY | S26: TOTAL P/DAY
A27: Bare_Rock | C27: =F54 -> 222.22222 | D27: =N53 -> 0.05479425 | E27: =O53 -> 117.0855 | F27: =P53 -> 3.969 | K27: Chickens, Broilers | L27: 95 | M27: 0.9 | N27: =L27*M27 -> 85.5 | O27: =N27/1000 -> 0.0855 | P27: 1.07 | Q27: 0.3 | R27: =O27*P27 -> 0.091485 | S27: =O27*Q27 -> 0.02565
A28: Sandy_Areas | C28: 0 | D28: 0 | E28: 0 | F28: 0 | K28: Chickens, Layers | L28: 0 | M28: 1.8 | N28: =L28*M28 -> 0 | O28: =N28/1000 -> 0 | P28: 0.85 | Q28: 0.29 | R28: =O28*P28 -> 0 | S28: =O28*Q28 -> 0
A29: Unpaved_Road | C29: 0 | D29: 0 | E29: 0 | F29: 0 | K29: Cows, Beef | L29: 91 | M29: 360 | N29: =L29*M29 -> 32760 | O29: =N29/1000 -> 32.76 | P29: 0.31 | Q29: 0.09 | R29: =O29*P29 -> 10.1556 | S29: =O29*Q29 -> 2.9484
A30: Ld_Mixed | C30: =F50+F51 -> 23372.84 | D30: =N54+N57 -> 146.01918 | E30: =O54+O57 -> 7171.983 | F30: =P54+P57 -> 771.75 | K30: Cows, Dairy | L30: 69 | M30: 640 | N30: =L30*M30 -> 44160 | O30: =N30/1000 -> 44.16 | P30: 0.44 | Q30: 0.07 | R30: =O30*P30 -> 19.4304 | S30: =O30*Q30 -> 3.0912
A31: Md_Mixed | C31: =F52 -> 3395.0617 | D31: =N55 -> 111.5805 | E31: =O55 -> 4522.6755 | F31: =P55 -> 462.8295 | K31: Horses | L31: 242 | M31: 500 | N31: =L31*M31 -> 121000 | O31: =N31/1000 -> 121 | P31: 0.28 | Q31: 0.06 | R31: =O31*P31 -> 33.88 | S31: =O31*Q31 -> 7.26
A32: Hd_Mixed | C32: =F53 -> 965.4321 | D32: =N56 -> 31.739211 | E32: =O56 -> 1286.397 | F32: =P56 -> 131.6385 | K32: Pigs/Hogs/Swine | L32: 323 | M32: 61 | N32: =L32*M32 -> 19703 | O32: =N32/1000 -> 19.703 | P32: 0.48 | Q32: 0.15 | R32: =O32*P32 -> 9.45744 | S32: =O32*Q32 -> 2.95545
A33: Ld_Residential | C33: 0 | D33: 0 | E33: 0 | F33: 0 | K33: Sheep | L33: 165 | M33: 50 | N33: =L33*M33 -> 8250 | O33: =N33/1000 -> 8.25 | P33: 0.37 | Q33: 0.1 | R33: =O33*P33 -> 3.0525 | S33: =O33*Q33 -> 0.825
A34: Md_Residential | C34: 0 | D34: 0 | E34: 0 | F34: 0 | K34: Turkeys | L34: 8 | M34: 6.8 | N34: =L34*M34 -> 54.4 | O34: =N34/1000 -> 0.0544 | P34: 0.59 | Q34: 0.2 | R34: =O34*P34 -> 0.032096 | S34: =O34*Q34 -> 0.01088
A35: Hd_Residential | C35: 0 | D35: 0 | E35: 0 | F35: 0
A36: Farm Animals | D36: =N58 -> 0 | E36: =O58 -> 4895.7615 | F36: =P58 -> 1294.1145 | P36: Daily Totals | R36: =SUM(R27:R34) -> 76.099521 | S36: =SUM(S27:S34) -> 17.11658
A37: Tile Drainage | D37: 0 | E37: 0 | F37: 0 | P37: Poultry Totals | R37: =R27+R28+R34 -> 0.123581 | S37: =S27+S28+S34 -> 0.03653
A38: Stream Bank | D38: =N59 -> 26700.07 | E38: =O59 -> 33246.99 | F38: =P59 -> 13291.74 | P38: Livestock Totals | R38: =SUM(R29:R33) -> 75.97594 | S38: =SUM(S29:S33) -> 17.08005
A39: Groundwater | D39: =N60 -> 0 | E39: =O60 -> 132221.06 | F39: =P60 -> 2404.5525 | P39: Poultry Fraction | R39: =R37/R38 -> 0.0016265807 | S39: =S37/S38 -> 0.0021387525
A40: Point Source | D40: =N61 -> 0 | E40: =O61 -> 121109.62 | F40: =P61 -> 67820.949 | P40: Livestock Fraction | R40: =R38/R36 -> 0.99837606 | S40: =S38/S36 -> 0.99786581
A41: Septic Systems | D41: =N62 -> 0 | E41: =O62 -> 10658.308 | F41: =P62 -> 0
K42: * These values can be obtained from the "Animal" tab in the "Analyze" section of a Model My Watershed run
A43: Totals | C43: =SUM(C20:C41) -> 40567.901 | D43: =SUM(D20:D41) -> 27452.939 | E43: =SUM(E20:E41) -> 321753.82 | F43: =SUM(F20:F41) -> 87800.013
A45: MMW NLCD Land Cover Categories for Watershed (from "Analyze" csv file) | H45: Pollutant Load Conversion from Metric to Standard Units (from "Model" csv file)
A47: TYPE | D47: AREA (km^2) | F47: AREA (acres) | H47: SOURCE | K47: SEDIMENT (kg) | L47: TOTAL N (kg) | M47: TOTAL P (kg) | N47: SEDIMENT (tons) | O47: TOTAL N (lbs) | P47: TOTAL P (lbs)
...

Sheet Landcover Loading Rates
A1: Look-Up Table for MMW Loading Rates
A2: =CONCATENATE("Watershed: ",'MMW Output'!B2) -> Watershed: User Specified
A3: =CONCATENATE("Year: ",'MMW Output'!C14) -> Year: User Specified
A4: =CONCATENATE("Source File: ",'MMW Output'!$C$12) -> Source File: User Specified | I4: =COLUMN(LoadRates[TSS_LoadRate_lbPerAcPerY]) -> 17
A6: Section 2: Landcover Loading Rates Look-Up Table
B9: TOTAL WATERSHED ANNUAL LOADS from Model My Watershed | O9: ANNUAL LAND USE LOADING RATES (lbs/acre) based on land use, stream bank and farm animal sources
O11: SEDIMENT | S11: NITROGEN | X11: PHOSPHORUS
B12: Source | C12: Area | D12: Runoff | E12: Erosion | G12: Sediment | H12: Dis N | J12: Total Nitrogen | K12: Dis P | M12: Total Phosphorus | O12: From Land Use | P12: From Stream Banks ① | Q12: TOTAL SEDIMENT LOADING RATE | S12: From Land Use | T12: From Stream Banks ① | U12: From Farm Animals ② | V12: TOTAL NITROGEN LOADING RATE | X12: From Land Use | Y12: From Stream Banks ① | Z12: From Farm Animals ② | AA12: TOTAL PHOSPHORUS LOADING RATE
B13: Units | C13: Acres | D13: inches | E13: Tons | G13: Tons | H13: Pounds | J13: Pounds | K13: Pounds | M13: Pounds | O13: lbs/acre | P13: lbs/acre | Q13: lbs/acre | S13: lbs/acre | T13: lbs/acre | U13: lbs/acre | V13: lbs/acre | X13: lbs/acre | Y13: lbs/acre | Z13: lbs/acre | AA13: lbs/acre
B14: Source | C14: area_ac | D14: runoff_in | E14: erosion_tons | F14: Column1 | G14: sediment_tons | H14: DN_lbs | I14: Column2 | J14: TN_lbs | K14: DP_lbs | L14: Column3 | M14: TP_lbs | N14: Column4 | O14: TSS_LoadRateLand_lbPerAcPerY | P14: TSS_LoadRateBanks_lbPerAcPerY | Q14: TSS_LoadRate_lbPerAcPerY | R14: Column5 | S14: TN_LoadRateLand_lbPerAcPerY | T14: TN_LoadRateBanks_lbPerAcPerY | U14: TN_LoadRateAnimal_lbPerAcPerY | V14: TN_LoadRate_lbPerAcPerY | W14: Column6 | X14: TP_LoadRateLand_lbPerAcPerY | Y14: TP_LoadRateBanks_lbPerAcPerY | Z14: TP_LoadRateAnimal_lbPerAcPerY | AA14: TP_LoadRate_lbPerAcPerY
A15: MapShed Land Use Categories | B15: Hay/Past | C15: =+'MMW Output'!C20 -> 1666.6667 | D15: =+'MMW Output'!#REF! -> #REF! | E15: =+'MMW Output'!#REF! -> #REF! | G15: =+'MMW Output'!D20 -> 136.61541 | H15: =+'MMW Output'!#REF! -> #REF! | J15: =+'MMW Output'!E20 -> 1861.461 | K15: =+'MMW Output'!#REF! -> #REF! | M15: =+'MMW Output'!F20 -> 687.519 | O15: =IF(C15=0,0,(G15*2000/C15)) -> 163.93849 | P15: =IF(C15=0,0,'Stream Bank Loading Rates'!C$145) -> 987.23631 | Q15: =SUM(O15:P15) -> 1151.1748 | S15: =IF(C15=0,0,ROUND((J15/C15),2)) -> 1.12 | T15: =IF(C15=0,0,ROUND('Stream Bank Loading Rates'!$K$145,2)) -> 0.61 | U15: =IF(C15=0,0,ROUND('Farm Animal Loading rates'!$D$33,2)) -> 2.27 | V15: =SUM(S15:U15) -> 4 | X15: =IF(C15=0,0,ROUND((M15/C15),2)) -> 0.41 | Y15: =IF(C15=0,0,ROUND('Stream Bank Loading Rates'!T$145,2)) -> 0.25 | Z15: =IF(C15=0,0,ROUND('Farm Animal Loading rates'!$E$33,2)) -> 0.6 | AA15: =SUM(X15:Z15) -> 1.26 | AB15: Hay/Past
B16: Cropland | C16: =+'MMW Output'!C21 -> 491.35802 | D16: =+'MMW Output'!#REF! -> #REF! | E16: =+'MMW Output'!#REF! -> #REF! | G16: =+'MMW Output'!D21 -> 316.40659 | H16: =+'MMW Output'!#REF! -> #REF! | J16: =+'MMW Output'!E21 -> 3203.424 | K16: =+'MMW Output'!#REF! -> #REF! | M16: =+'MMW Output'!F21 -> 838.1205 | O16: =IF(C16=0,0,(G16*2000/C16)) -> 1287.8861 | P16: =IF(C16=0,0,'Stream Bank Loading Rates'!C$145) -> 987.23631 | Q16: =SUM(O16:P16) -> 2275.1224 | S16: =IF(C16=0,0,ROUND((J16/C16),2)) -> 6.52 | T16: =IF(C16=0,0,ROUND('Stream Bank Loading Rates'!$K$145,2)) -> 0.61 | U16: =IF(C16=0,0,ROUND('Farm Animal Loading rates'!$D$33,2)) -> 2.27 | V16: =SUM(S16:U16) -> 9.4 | X16: =IF(C16=0,0,ROUND((M16/C16),2)) -> 1.71 | Y16: =IF(C16=0,0,ROUND('Stream Bank Loading Rates'!T$145,2)) -> 0.25 | Z16: =IF(C16=0,0,ROUND('Farm Animal Loading rates'!$E$33,2)) -> 0.6 | AA16: =SUM(X16:Z16) -> 2.56 | AB16: Cropland
B17: Forest | C17: =+'MMW Output'!C22 -> 9730.8642 | D17: =+'MMW Output'!#REF! -> #REF! | E17: =+'MMW Output'!#REF! -> #REF! | G17: =+'MMW Output'!D22 -> 7.9434023 | H17: =+'MMW Output'!#REF! -> #REF! | J17: =+'MMW Output'!E22 -> 1136.898 | K17: =+'MMW Output'!#REF! -> #REF! | M17: =+'MMW Output'!F22 -> 73.647 | O17: =IF(C17=0,0,(G17*2000/C17)) -> 1.6326201 | P17: =IF(C17=0,0,'Stream Bank Loading Rates'!C$145) -> 987.23631 | Q17: =SUM(O17:P17) -> 988.86893 | S17: =IF(C17=0,0,ROUND((J17/C17),2)) -> 0.12 | T17: =IF(C17=0,0,ROUND('Stream Bank Loading Rates'!$K$145,2)) -> 0.61 | U17: n/a | V17: =SUM(S17:U17) -> 0.73 | X17: =IF(C17=0,0,ROUND((M17/C17),2)) -> 0.01 | Y17: =IF(C17=0,0,ROUND('Stream Bank Loading Rates'!T$145,2)) -> 0.25 | Z17: n/a | AA17: =SUM(X17:Z17) -> 0.26 | AB17: Forest
B18: Wetland | C18: =+'MMW Output'!C23 -> 656.79012 | D18: =+'MMW Output'!#REF! -> #REF! | E18: =+'MMW Output'!#REF! -> #REF! | G18: =+'MMW Output'!D23 -> 0.7252245 | H18: =+'MMW Output'!#REF! -> #REF! | J18: =+'MMW Output'!E23 -> 254.457 | K18: =+'MMW Output'!#REF! -> #REF! | M18: =+'MMW Output'!F23 -> 14.553 | O18: =IF(C18=0,0,(G18*2000/C18)) -> 2.2083904 | P18: =IF(C18=0,0,'Stream Bank Loading Rates'!C$145) -> 987.23631 | Q18: =SUM(O18:P18) -> 989.4447 | S18: =IF(C18=0,0,ROUND((J18/C18),2)) -> 0.39 | T18: =IF(C18=0,0,ROUND('Stream Bank Loading Rates'!$K$145,2)) -> 0.61 | U18: n/a | V18: =SUM(S18:U18) -> 1 | X18: =IF(C18=0,0,ROUND((M18/C18),2)) -> 0.02 | Y18: =IF(C18=0,0,ROUND('Stream Bank Loading Rates'!T$145,2)) -> 0.25 | Z18: n/a | AA18: =SUM(X18:Z18) -> 0.27 | AB18: Wetland
B19: Disturbed | C19: =+'MMW Output'!C24 -> 0 | D19: =+'MMW Output'!#REF! -> #REF! | E19: =+'MMW Output'!#REF! -> #REF! | G19: =+'MMW Output'!D24 -> 0 | H19: =+'MMW Output'!#REF! -> #REF! | J19: =+'MMW Output'!E24 -> 0 | K19: =+'MMW Output'!#REF! -> #REF! | M19: =+'MMW Output'!F24 -> 0 | O19: =IF(C19=0,0,(G19*2000/C19)) -> 0 | P19: =IF(C19=0,0,'Stream Bank Loading Rates'!C$145) -> 0 | Q19: =SUM(O19:P19) -> 0 | S19: =IF(C19=0,0,ROUND((J19/C19),2)) -> 0 | T19: =IF(C19=0,0,ROUND('Stream Bank Loading Rates'!$K$145,2)) -> 0 | U19: n/a | V19: =SUM(S19:U19) -> 0 | X19: =IF(C19=0,0,ROUND((M19/C19),2)) -> 0 | Y19: =IF(C19=0,0,ROUND('Stream Bank Loading Rates'!T$145,2)) -> 0 | Z19: n/a | AA19: =SUM(X19:Z19) -> 0 | AB19: Disturbed
B20: Turfgrass | C20: =+'MMW Output'!C25 -> 0 | D20: =+'MMW Output'!#REF! -> #REF! | E20: =+'MMW Output'!#REF! -> #REF! | G20: =+'MMW Output'!D25 -> 0 | H20: =+'MMW Output'!#REF! -> #REF! | J20: =+'MMW Output'!E25 -> 0 | K20: =+'MMW Output'!#REF! -> #REF! | M20: =+'MMW Output'!F25 -> 0 | O20: =IF(C20=0,0,(G20*2000/C20)) -> 0 | P20: =IF(C20=0,0,'Stream Bank Loading Rates'!C$145) -> 0 | Q20: =SUM(O20:P20) -> 0 | S20: =IF(C20=0,0,ROUND((J20/C20),2)) -> 0 | T20: =IF(C20=0,0,ROUND('Stream Bank Loading Rates'!$K$145,2)) -> 0 | U20: n/a | V20: =SUM(S20:U20) -> 0 | X20: =IF(C20=0,0,ROUND((M20/C20),2)) -> 0 | Y20: =IF(C20=0,0,ROUND('Stream Bank Loading Rates'!T$145,2)) -> 0 | Z20: n/a | AA20: =SUM(X20:Z20) -> 0 | AB20: Turfgrass
B21: Open_Land | C21: =+'MMW Output'!C26 -> 66.666667 | D21: =+'MMW Output'!#REF! -> #REF! | E21: =+'MMW Output'!#REF! -> #REF! | G21: =+'MMW Output'!D26 -> 1.7845065 | H21: =+'MMW Output'!#REF! -> #REF! | J21: =+'MMW Output'!E26 -> 67.6935 | K21: =+'MMW Output'!#REF! -> #REF! | M21: =+'MMW Output'!F26 -> 4.6305 | O21: =IF(C21=0,0,(G21*2000/C21)) -> 53.535195 | P21: =IF(C21=0,0,'Stream Bank Loading Rates'!C$145) -> 987.23631 | Q21: =SUM(O21:P21) -> 1040.7715 | S21: =IF(C21=0,0,ROUND((J21/C21),2)) -> 1.02 | T21: =IF(C21=0,0,ROUND('Stream Bank Loading Rates'!$K$145,2)) -> 0.61 | U21: n/a | V21: =SUM(S21:U21) -> 1.63 | X21: =IF(C21=0,0,ROUND((M21/C21),2)) -> 0.07 | Y21: =IF(C21=0,0,ROUND('Stream Bank Loading Rates'!T$145,2)) -> 0.25 | Z21: n/a | AA21: =SUM(X21:Z21) -> 0.32 | AB21: Open_Land
B22: Bare_Rock | C22: =+'MMW Output'!C27 -> 222.22222 | D22: =+'MMW Output'!#REF! -> #REF! | E22: =+'MMW Output'!#REF! -> #REF! | G22: =+'MMW Output'!D27 -> 0.05479425 | H22: =+'MMW Output'!#REF! -> #REF! | J22: =+'MMW Output'!E27 -> 117.0855 | K22: =+'MMW Output'!#REF! -> #REF! | M22: =+'MMW Output'!F27 -> 3.969 | O22: =IF(C22=0,0,(G22*2000/C22)) -> 0.49314825 | P22: =IF(C22=0,0,'Stream Bank Loading Rates'!C$145) -> 987.23631 | Q22: =SUM(O22:P22) -> 987.72946 | S22: =IF(C22=0,0,ROUND((J22/C22),2)) -> 0.53 | T22: =IF(C22=0,0,ROUND('Stream Bank Loading Rates'!$K$145,2)) -> 0.61 | U22: n/a | V22: =SUM(S22:U22) -> 1.14 | X22: =IF(C22=0,0,ROUND((M22/C22),2)) -> 0.02 | Y22: =IF(C22=0,0,ROUND('Stream Bank Loading Rates'!T$145,2)) -> 0.25 | Z22: n/a | AA22: =SUM(X22:Z22) -> 0.27 | AB22: Bare_Rock
B23: Sandy_Areas | C23: =+'MMW Output'!C28 -> 0 | D23: =+'MMW Output'!#REF! -> #REF! | E23: =+'MMW Output'!#REF! -> #REF! | G23: =+'MMW Output'!D28 -> 0 | H23: =+'MMW Output'!#REF! -> #REF! | J23: =+'MMW Output'!E28 -> 0 | K23: =+'MMW Output'!#REF! -> #REF! | M23: =+'MMW Output'!F28 -> 0 | O23: =IF(C23=0,0,(G23*2000/C23)) -> 0 | P23: =IF(C23=0,0,'Stream Bank Loading Rates'!C$145) -> 0 | Q23: =SUM(O23:P23) -> 0 | S23: =IF(C23=0,0,ROUND((J23/C23),2)) -> 0 | T23: =IF(C23=0,0,ROUND('Stream Bank Loading Rates'!$K$145,2)) -> 0 | U23: n/a | V23: =SUM(S23:U23) -> 0 | X23: =IF(C23=0,0,ROUND((M23/C23),2)) -> 0 | Y23: =IF(C23=0,0,ROUND('Stream Bank Loading Rates'!T$145,2)) -> 0 | Z23: n/a | AA23: =SUM(X23:Z23) -> 0 | AB23: Sandy_Areas
B24: Unpaved_Road | C24: =+'MMW Output'!C29 -> 0 | D24: =+'MMW Output'!#REF! -> #REF! | E24: =+'MMW Output'!#REF! -> #REF! | G24: =+'MMW Output'!D29 -> 0 | H24: =+'MMW Output'!#REF! -> #REF! | J24: =+'MMW Output'!E29 -> 0 | K24: =+'MMW Output'!#REF! -> #REF! | M24: =+'MMW Output'!F29 -> 0 | O24: =IF(C24=0,0,(G24*2000/C24)) -> 0 | P24: =IF(C24=0,0,'Stream Bank Loading Rates'!C$145) -> 0 | Q24: =SUM(O24:P24) -> 0 | S24: =IF(C24=0,0,ROUND((J24/C24),2)) -> 0 | T24: =IF(C24=0,0,ROUND('Stream Bank Loading Rates'!$K$145,2)) -> 0 | U24: n/a | V24: =SUM(S24:U24) -> 0 | X24: =IF(C24=0,0,ROUND((M24/C24),2)) -> 0 | Y24: =IF(C24=0,0,ROUND('Stream Bank Loading Rates'!T$145,2)) -> 0 | Z24: n/a | AA24: =SUM(X24:Z24) -> 0 | AB24: Unpaved_Road
B25: Ld_Mixed | C25: =+'MMW Output'!C30 -> 23372.84 | D25: =+'MMW Output'!#REF! -> #REF! | E25: =+'MMW Output'!#REF! -> #REF! | G25: =+'MMW Output'!D30 -> 146.01918 | H25: =+'MMW Output'!#REF! -> #REF! | J25: =+'MMW Output'!E30 -> 7171.983 | K25: =+'MMW Output'!#REF! -> #REF! | M25: =+'MMW Output'!F30 -> 771.75 | O25: =IF(C25=0,0,(G25*2000/C25)) -> 12.494774 | P25: =IF(C25=0,0,'Stream Bank Loading Rates'!E131) -> 1314.9097 | Q25: =SUM(O25:P25) -> 1327.4045 | S25: =IF(C25=0,0,ROUND((J25/C25),2)) -> 0.31 | T25: =IF(C25=0,0,ROUND('Stream Bank Loading Rates'!M131,2)) -> 0.72 | U25: n/a | V25: =SUM(S25:U25) -> 1.03 | X25: =IF(C25=0,0,ROUND((M25/C25),2)) -> 0.03 | Y25: =IF(C25=0,0,ROUND('Stream Bank Loading Rates'!V131,2)) -> 0.33 | Z25: n/a | AA25: =SUM(X25:Z25) -> 0.36 | AB25: Ld_Mixed
B26: Md_Mixed | C26: =+'MMW Output'!C31 -> 3395.0617 | D26: =+'MMW Output'!#REF! -> #REF! | E26: =+'MMW Output'!#REF! -> #REF! | G26: =+'MMW Output'!D31 -> 111.5805 | H26: =+'MMW Output'!#REF! -> #REF! | J26: =+'MMW Output'!E31 -> 4522.6755 | K26: =+'MMW Output'!#REF! -> #REF! | M26: =+'MMW Output'!F31 -> 462.8295 | O26: =IF(C26=0,0,(G26*2000/C26)) -> 65.731056 | P26: =IF(C26=0,0,'Stream Bank Loading Rates'!E132) -> 2123.1708 | Q26: =SUM(O26:P26) -> 2188.9019 | S26: =IF(C26=0,0,ROUND((J26/C26),2)) -> 1.33 | T26: =IF(C26=0,0,ROUND('Stream Bank Loading Rates'!M132,2)) -> 1.75 | U26: n/a | V26: =SUM(S26:U26) -> 3.08 | X26: =IF(C26=0,0,ROUND((M26/C26),2)) -> 0.14 | Y26: =IF(C26=0,0,ROUND('Stream Bank Loading Rates'!V132,2)) -> 0.53 | Z26: n/a | AA26: =SUM(X26:Z26) -> 0.67 | AB26: Md_Mixed
B27: Hd_Mixed | C27: =+'MMW Output'!C32 -> 965.4321 | D27: =+'MMW Output'!#REF! -> #REF! | E27: =+'MMW Output'!#REF! -> #REF! | G27: =+'MMW Output'!D32 -> 31.739211 | H27: =+'MMW Output'!#REF! -> #REF! | J27: =+'MMW Output'!E32 -> 1286.397 | K27: =+'MMW Output'!#REF! -> #REF! | M27: =+'MMW Output'!F32 -> 131.6385 | O27: =IF(C27=0,0,(G27*2000/C27)) -> 65.751307 | P27: =IF(C27=0,0,'Stream Bank Loading Rates'!E133) -> 2887.7421 | Q27: =SUM(O27:P27) -> 2953.4934 | S27: =IF(C27=0,0,ROUND((J27/C27),2)) -> 1.33 | T27: =IF(C27=0,0,ROUND('Stream Bank Loading Rates'!M133,2)) -> 2.73 | U27: n/a | V27: =SUM(S27:U27) -> 4.06 | X27: =IF(C27=0,0,ROUND((M27/C27),2)) -> 0.14 | Y27: =IF(C27=0,0,ROUND('Stream Bank Loading Rates'!V133,2)) -> 0.72 | Z27: n/a | AA27: =SUM(X27:Z27) -> 0.86 | AB27: Hd_Mixed
B28: Ld_Residential | C28: =+'MMW Output'!C33 -> 0 | G28: =+'MMW Output'!D33 -> 0 | J28: =+'MMW Output'!E33 -> 0 | M28: =+'MMW Output'!F33 -> 0 | O28: =IF(C28=0,0,(G28*2000/C28)) -> 0 | P28: =IF(C28=0,0,'Stream Bank Loading Rates'!E134) -> 0 | Q28: =SUM(O28:P28) -> 0 | S28: =IF(C28=0,0,ROUND((J28/C28),2)) -> 0 | T28: =IF(C28=0,0,ROUND('Stream Bank Loading Rates'!M134,2)) -> 0 | U28: n/a | V28: =SUM(S28:U28) -> 0 | X28: =IF(C28=0,0,ROUND((M28/C28),2)) -> 0 | Y28: =IF(C28=0,0,ROUND('Stream Bank Loading Rates'!V134,2)) -> 0 | Z28: n/a | AA28: =SUM(X28:Z28) -> 0 | AB28: Ld_Residential
B29: Md_Residential | C29: =+'MMW Output'!C34 -> 0 | G29: =+'MMW Output'!D34 -> 0 | J29: =+'MMW Output'!E34 -> 0 | M29: =+'MMW Output'!F34 -> 0 | O29: =IF(C29=0,0,(G29*2000/C29)) -> 0 | P29: =IF(C29=0,0,'Stream Bank Loading Rates'!E135) -> 0 | Q29: =SUM(O29:P29) -> 0 | S29: =IF(C29=0,0,ROUND((J29/C29),2)) -> 0 | T29: =IF(C29=0,0,ROUND('Stream Bank Loading Rates'!M135,2)) -> 0 | U29: n/a | V29: =SUM(S29:U29) -> 0 | X29: =IF(C29=0,0,ROUND((M29/C29),2)) -> 0 | Y29: =IF(C29=0,0,ROUND('Stream Bank Loading Rates'!V135,2)) -> 0 | Z29: n/a | AA29: =SUM(X29:Z29) -> 0 | AB29: Md_Residential
B30: Hd_Residential | C30: =+'MMW Output'!C35 -> 0 | G30: =+'MMW Output'!D35 -> 0 | J30: =+'MMW Output'!E35 -> 0 | M30: =+'MMW Output'!F35 -> 0 | O30: =IF(C30=0,0,(G30*2000/C30)) -> 0 | P30: =IF(C30=0,0,'Stream Bank Loading Rates'!E136) -> 0 | Q30: =SUM(O30:P30) -> 0 | S30: =IF(C30=0,0,ROUND((J30/C30),2)) -> 0 | T30: =IF(C30=0,0,ROUND('Stream Bank Loading Rates'!M136,2)) -> 0 | U30: n/a | V30: =SUM(S30:U30) -> 0 | X30: =IF(C30=0,0,ROUND((M30/C30),2)) -> 0 | Y30: =IF(C30=0,0,ROUND('Stream Bank Loading Rates'!V136,2)) -> 0 | Z30: n/a | AA30: =SUM(X30:Z30) -> 0 | AB30: Hd_Residential
A32: Addt'l Sources | B32: Source | G32: Sediment | J32: Total Nitrogen | K32: Dis P | M32: Total Phosphorus | O32: Tons * 2000 lbs/ton acres of a land use | Q32: Sum of previous two sources | S32: Tons * 2000 lbs/ton acres of a land use | V32: Sum of previous three sources | X32: Tons * 2000 lbs/ton acres of a land use | AA32: Sum of previous three sources
B33: Units | D33: inches | E33: Tons | G33: Tons | J33: Pounds | K33: Pounds | M33: Pounds
B34: Farm Animals | C34: =+'MMW Output'!C36 | D34: =+'MMW Output'!#REF! -> #REF! | E34: =+'MMW Output'!#REF! -> #REF! | G34: =+'MMW Output'!D36 -> 0 | H34: =+'MMW Output'!#REF! -> #REF! | J34: =+'MMW Output'!E36 -> 4895.7615 | K34: =+'MMW Output'!#REF! -> #REF! | M34: =+'MMW Output'!F36 -> 1294.1145
B35: Tile Drainage | C35: =+'MMW Output'!C37 | D35: =+'MMW Output'!#REF! -> #REF! | E35: =+'MMW Output'!#REF! -> #REF! | G35: =+'MMW Output'!D37 -> 0 | H35: =+'MMW Output'!#REF! -> #REF! | J35: =+'MMW Output'!E37 -> 0 | K35: =+'MMW Output'!#REF! -> #REF! | M35: =+'MMW Output'!F37 -> 0
B36: Stream Bank ① | C36: =+'MMW Output'!C38 | D36: =+'MMW Output'!#REF! -> #REF! | E36: =+'MMW Output'!#REF! -> #REF! | G36: =+'MMW Output'!D38 -> 26700.07 | H36: =+'MMW Output'!#REF! -> #REF! | J36: =+'MMW Output'!E38 -> 33246.99 | K36: =+'MMW Output'!#REF! -> #REF! | M36: =+'MMW Output'!F38 -> 13291.74
B37: Groundwater | G37: 0 | J37: =+'MMW Output'!E39 -> 132221.06 | M37: =+'MMW Output'!F39 -> 2404.5525
B38: Point Source | G38: 0 | J38: =+'MMW Output'!E40 -> 121109.62 | M38: =+'MMW Output'!F40 -> 67820.949
B39: Septic Systems | G39: 0 | J39: =+'MMW Output'!E41 -> 10658.308 | M39: =+'MMW Output'!F41 -> 0
B43: Notes:
B44: ① - Separate worksheets are used to calculate and apportion the loading rates from the Stream Bank source loads (for sediment, total nitrogen, and total phosphorus) from the MMW Output file into each land use category, using methodology provided by Dr. Barry Evans (Pennsylvania State University), the author of MapShed, and with concurrence from Mr. Bill Brown (PADEP).
B45: ② - A separate worksheet is used to calculate and apportion the "Total Nitrogen" and "Total Phosphorus" loading rates from the Farm Animals source load from the MMW Output file into the two agricultural land uses, Hay/Pasture and Cropland, based on area weighting. The methodology was provided by Dr. Barry Evans (Pennsylvania State University), the author of MapShed, and with concurrence from Mr. Bill Brown (PADEP). Additionally, since the Farm Animals source loads do not apply to other land use catergories, the values in those cells are "n/a".
B46: Groundwater | C46: =+'MMW Output'!C39 | D46: =+'MMW Output'!#REF! -> #REF! | E46: =+'MMW Output'!#REF! -> #REF! | G46: =+'MMW Output'!D39 -> 0 | H46: =+'MMW Output'!#REF! -> #REF! | J46: =+'MMW Output'!E39 -> 132221.06 | K46: =+'MMW Output'!#REF! -> #REF! | M46: =+'MMW Output'!F39 -> 2404.5525
B47: Point Source | C47: =+'MMW Output'!C40 | D47: =+'MMW Output'!#REF! -> #REF! | E47: =+'MMW Output'!#REF! -> #REF! | G47: =+'MMW Output'!D40 -> 0 | H47: =+'MMW Output'!#REF! -> #REF! | J47: =+'MMW Output'!E40 -> 121109.62 | K47: =+'MMW Output'!#REF! -> #REF! | M47: =+'MMW Output'!F40 -> 67820.949
B48: Septic Systems | C48: =+'MMW Output'!C41 | D48: =+'MMW Output'!#REF! -> #REF! | E48: =+'MMW Output'!#REF! -> #REF! | G48: =+'MMW Output'!D41 -> 0 | H48: =+'MMW Output'!#REF! -> #REF! | J48: =+'MMW Output'!E41 -> 10658.308 | K48: =+'MMW Output'!#REF! -> #REF! | M48: =+'MMW Output'!F41 -> 0

Sheet Farm Animal Loading rates
A1: Look-Up Table for MMW Loading Rates
A2: =CONCATENATE("Watershed: ",'MMW Output'!B2) -> Watershed: User Specified
A3: =CONCATENATE("Year: ",'MMW Output'!C14) -> Year: User Specified
A5: Section 4: Farm Animals TN and TP Loading Rates Worksheet
A6: This worksheet calculates and apportions the "Total Nitrogen" and "Total Phosphorus" loading rates from the "Farm Animals" source load from a MMW Output file into the two applicable agricultural land uses, Hay/Pasture and Cropland, based on area weighting. The methodology was provided by Dr. Barry Evans (Stroud Water Research Center, Pennsylvania State University), the author of MapShed, and with concurrence from Mr. Bill Brown (PADEP). The MapShed output file provides the Farm Animals "Total Nitrogen" and "Total Phosphorus" loads in pounds.
A9: Step 1. The Farm Animal "Total Nitrogen" and "Total Phosphorus" load, in pounds, and land areas for each land use category, in acres, from a MMW Output file are presented below.
B12: Total Watershed Load | D12: Total Nitrogen | E12: Total Phosphorus
C13: Nutrient Load from Farm Animals | D13: =+'MMW Output'!E36 -> 4895.7615 | E13: =+'MMW Output'!F36 -> 1294.1145 | F13: pounds | G13: Note: The loads are taken from cells E36 and F36 from the MMW Output worksheet
B15: Land Use Categories from MMW ①
C16: Source | D16: Area (acres)
C17: Hay/Pasture | D17: =+'MMW Output'!C20 -> 1666.6667
C18: Cropland | D18: =+'MMW Output'!C21 -> 491.35802
B19: ① - Since only the 'Hay/Pasture' and 'Cropland' land uses are apportioned Farm Loading Rates, the remaining land use categories are not applicable to this worksheet.
A22: Step 2. Total Acres in "Hay/Pasture" and "Cropland" land uses are summed.
C24: Area of Hay/Pasture & Cropland, acres | D24: =+D17+D18 -> 2158.0247 | E24: acres = | F24: =CONCATENATE("[ ",ROUND(D17,2)," acres + ",ROUND(D18,2)," acres"," ]") -> [ 1666.67 acres + 491.36 acres ]
A27: Step 3. Calculate the unit area Farm Animals loading rate (lbs/ac) to Total Nitrogen and Total Phosphorus for each land use by dividing the Farm Animal Load by the land use acres.
D29: Total Nitrogen | E29: Total Phosphorus
C30: Nutrient Load from Farm Animals | D30: =+D13 -> 4895.7615 | E30: =+E13 -> 1294.1145 | F30: pounds, from Step 1
C31: Area of Hay/Pasture & Cropland | D31: =+D24 -> 2158.0247 | E31: =+D24 -> 2158.0247 | F31: acres, from Step 2
C33: Loading Rate for Hay/Pasture & Cropland | D33: =+D30/D31 -> 2.2686309 | E33: =+E30/E31 -> 0.59967548 | F33: pounds per acre
A36: Step 4. Add these Farm Animals loading rates to the Land Use (upland) and Stream Bank loading rates for Hay/Pasture and Cropland to calculate the Toal Nitrogen and Total Phosphorus loading rates as shown on the Land Use Loading Rates Look-Up Table.

Sheet Stream Bank Loading Rates
A1: Look-Up Table for MMW Loading Rates | I1: Look-Up Table for MMW Loading Rates | R1: Look-Up Table for MMW Loading Rates
A2: =CONCATENATE("Watershed: ",'MMW Output'!$B$2) -> Watershed: User Specified | I2: =CONCATENATE("Watershed: ",'MMW Output'!$B$2) -> Watershed: User Specified | R2: =CONCATENATE("Watershed: ",'MMW Output'!$B$2) -> Watershed: User Specified
A3: =CONCATENATE("Year: ",'MMW Output'!$C$14) -> Year: User Specified | I3: =CONCATENATE("Year: ",'MMW Output'!$C$14) -> Year: User Specified | R3: =CONCATENATE("Year: ",'MMW Output'!$C$14) -> Year: User Specified
A5: Section 5: Stream Bank Sediment Loading Rates Worksheet | I5: Section 6: Stream Bank Nitrogen Loading Rates Worksheet | R5: Section 7: Stream Bank Phosphorus Loading Rates Worksheet
A6: This worksheet calculates and apportions the loading rates from the Stream Bank source load for sediment from the MMW Output file into each land use category, using methodology provided from Dr. Barry Evans (Pennsylvania State University), the author of MapShed, and with concurrence from Mr. Bill Brown (PADEP). The MMW output file provides the sediment load in tons, which are converted to pounds to be consistent with the loading rates for Total Nitrogen and Total Phosphorus. | I6: This worksheet calculates and apportions the loading rates from the Stream Bank source load for Total Nitrogen from the Christina MapShed Output file into each land use category, using methodology provided from Dr. Barry Evans (Pennsylvania State University), the author of MapShed, and with concurrence from Mr. Bill Brown (PADEP). The MapShed output file provides the nitrogen load in pounds. | R6: This worksheet calculates and apportions the loading rates from the Stream Bank source load for Total Phosphorus from the MMW Output file into each land use category, using methodology provided from Dr. Barry Evans (Pennsylvania State University), the author of MapShed, and with concurrence from Mr. Bill Brown (PADEP). The MapShed output file provides the Phosphorus load in pounds.
A9: Step 1. The Stream Bank Sediment Load, in tons, and land areas for each land use category, in acres, are presented below. | I9: Step 1. The land areas for each land use category, in acres, are presented below. | R9: Step 1. The land areas for each land use category, in acres, are presented below.
C11: Sediment
B12: Stream Bank | C12: =ROUND('MMW Output'!D38,2) -> 26700.07 | D12: tons | E12: Note: The sediment load is taken from Cell D38 in the MMW Output worksheet
B14: Source | C14: Area (acres) | J14: Source | K14: Area (acres) | S14: Source | T14: Area (acres)
A15: Land Use Categories from MapShed | B15: Hay/Pasture | C15: =+'MMW Output'!C20 -> 1666.6667 | I15: Land Use Categories from MapShed | J15: Hay/Pasture | K15: =+'MMW Output'!C20 -> 1666.6667 | R15: Land Use Categories from MapShed | S15: Hay/Pasture | T15: =+'MMW Output'!C20 -> 1666.6667
B16: Cropland | C16: =+'MMW Output'!C21 -> 491.35802 | J16: Cropland | K16: =+'MMW Output'!C21 -> 491.35802 | S16: Cropland | T16: =+'MMW Output'!C21 -> 491.35802
B17: Forest | C17: =+'MMW Output'!C22 -> 9730.8642 | J17: Forest | K17: =+'MMW Output'!C22 -> 9730.8642 | S17: Forest | T17: =+'MMW Output'!C22 -> 9730.8642
B18: Wetland | C18: =+'MMW Output'!C23 -> 656.79012 | J18: Wetland | K18: =+'MMW Output'!C23 -> 656.79012 | S18: Wetland | T18: =+'MMW Output'!C23 -> 656.79012
B19: Disturbed | C19: =+'MMW Output'!C24 -> 0 | J19: Disturbed | K19: =+'MMW Output'!C24 -> 0 | S19: Disturbed | T19: =+'MMW Output'!C24 -> 0
B20: Turfgrass | C20: =+'MMW Output'!C25 -> 0 | J20: Turfgrass | K20: =+'MMW Output'!C25 -> 0 | S20: Turfgrass | T20: =+'MMW Output'!C25 -> 0
B21: Open_Land | C21: =+'MMW Output'!C26 -> 66.666667 | J21: Open_Land | K21: =+'MMW Output'!C26 -> 66.666667 | S21: Open_Land | T21: =+'MMW Output'!C26 -> 66.666667
B22: Bare_Rock | C22: =+'MMW Output'!C27 -> 222.22222 | J22: Bare_Rock | K22: =+'MMW Output'!C27 -> 222.22222 | S22: Bare_Rock | T22: =+'MMW Output'!C27 -> 222.22222
B23: Sandy_Areas | C23: =+'MMW Output'!C28 -> 0 | J23: Sandy_Areas | K23: =+'MMW Output'!C28 -> 0 | S23: Sandy_Areas | T23: =+'MMW Output'!C28 -> 0
B24: Unpaved_Road | C24: =+'MMW Output'!C29 -> 0 | J24: Unpaved_Road | K24: =+'MMW Output'!C29 -> 0 | S24: Unpaved_Road | T24: =+'MMW Output'!C29 -> 0
B25: Ld_Mixed | C25: =+'MMW Output'!C30 -> 23372.84 | J25: Ld_Mixed | K25: =+'MMW Output'!C30 -> 23372.84 | S25: Ld_Mixed | T25: =+'MMW Output'!C30 -> 23372.84
B26: Md_Mixed | C26: =+'MMW Output'!C31 -> 3395.0617 | J26: Md_Mixed | K26: =+'MMW Output'!C31 -> 3395.0617 | S26: Md_Mixed | T26: =+'MMW Output'!C31 -> 3395.0617
B27: Hd_Mixed | C27: =+'MMW Output'!C32 -> 965.4321 | J27: Hd_Mixed | K27: =+'MMW Output'!C32 -> 965.4321 | S27: Hd_Mixed | T27: =+'MMW Output'!C32 -> 965.4321
... B30: Hd_Residential | C30: =+'MMW Output'!C35 -> 0 | J30: Hd_Residential | K30: =+'MMW Output'!C35 -> 0 | S30: Hd_Residential | T30: =+'MMW Output'!C35 -> 0
B32: Total Acres, Watershed | C32: =SUM(C15:C31) -> 40567.901 | J32: Total Acres, Watershed | K32: =SUM(K15:K31) -> 40567.901 | S32: Total Acres, Watershed | T32: =SUM(T15:T31) -> 40567.901
A34: Step 2. Convert the Stream Bank Sediment Load to pounds by multiplying tons by 2,000 pounds per ton. | I34: Step 2. The Stream Bank Total Nitrogen Load, in pounds, is presented below: | R34: Step 2. The Stream Bank Total Phosphorus Load, in pounds, is presented below:
C36: Sediment Load, pounds | K36: Total Nitrogen Load, pounds | T36: Total Phosphorus Load, pounds
B37: Stream Bank | C37: =+C12*2000 -> 53400140 | D37: pounds | E37: =CONCATENATE("= [ ",ROUND(C12,2)," tons x 2,000 pounds per ton]") -> = [ 26700.07 tons x 2,000 pounds per ton] | J37: Stream Bank | K37: =+'MMW Output'!E38 -> 33246.99 | L37: pounds | S37: Stream Bank | T37: =+'MMW Output'!F38 -> 13291.74 | U37: pounds
A40: =CONCATENATE("Step 3. Sum the total acres in the ", 'MMW Output'!C13," watershed.") -> Step 3. Sum the total acres in the User Specified watershed. | I40: =CONCATENATE("Step 3. Sum the total acres in the ", 'MMW Output'!C13," watershed.") -> Step 3. Sum the total acres in the User Specified watershed. | R40: =CONCATENATE("Step 3. Sum the total acres in the ", 'MMW Output'!C13," watershed.") -> Step 3. Sum the total acres in the User Specified watershed.
B42: Total Acres in watershed | C42: =SUM(C15:C31) -> 40567.901 | D42: acres | J42: Total Acres in watershed | K42: =SUM(K15:K31) -> 40567.901 | L42: acres | S42: Total Acres in watershed | T42: =SUM(T15:T31) -> 40567.901 | U42: acres
A45: Step 4. Calculate the total acres in the watershed that are considered "Developed," which includes Low Density Mixed (Ld_Mixed), Medium Density Mixed (Md_Mixed), High Density Mixed (Hd_Mixed); and Low Density Residential (Ld_Residential), Medium Density Residential (Md_Residential), and High Density Residential (Hd_Residential). | I45: Step 4. Calculate the total acres in the watershed that are considered "Developed," which includes Low Density Mixed (Ld_Mixed), Medium Density Mixed (Md_Mixed), High Density Mixed (Hd_Mixed); and Low Density Residential (Ld_Residential), Medium Density Residential (Md_Residential), and High Density Residential (Hd_Residential): | R45: Step 4. Calculate the total acres in the watershed that are considered "Developed," which includes Low Density Mixed (Ld_Mixed), Medium Density Mixed (Md_Mixed), High Density Mixed (Hd_Mixed); and Low Density Residential (Ld_Residential), Medium Density Residential (Md_Residential), and High Density Residential (Hd_Residential):
B47: Area of Developed Lands | C47: acres | D47: percent | J47: Area of Developed Lands | K47: acres | L47: percent | S47: Area of Developed Lands | T47: acres | U47: percent
B48: Low Density Developed | C48: =+C25+C28 -> 23372.84 | D48: =+C48/C$51 -> 0.84277066 | E48: [ Ld_Mixed + Ld_Residential ] | J48: Low Density Developed | K48: =+K25+K28 -> 23372.84 | L48: =+K48/K$51 -> 0.84277066 | M48: [ Ld_Mixed + Ld_Residential ] | S48: Low Density Developed | T48: =+T25+T28 -> 23372.84 | U48: =+T48/T$51 -> 0.84277066 | V48: [ Ld_Mixed + Ld_Residential ]
B49: Medium Density Developed | C49: =+C26+C29 -> 3395.0617 | D49: =+C49/C$51 -> 0.12241809 | E49: [ Md_Mixed + Md_Residential ] | J49: Medium Density Developed | K49: =+K26+K29 -> 3395.0617 | L49: =+K49/K$51 -> 0.12241809 | M49: [ Md_Mixed + Md_Residential ] | S49: Medium Density Developed | T49: =+T26+T29 -> 3395.0617 | U49: =+T49/T$51 -> 0.12241809 | V49: [ Md_Mixed + Md_Residential ]
B50: High Density Developed | C50: =+C27+C30 -> 965.4321 | D50: =+C50/C$51 -> 0.034811254 | E50: [ Hd_Mixed + Hd_Residential ] | J50: High Density Developed | K50: =+K27+K30 -> 965.4321 | L50: =+K50/K$51 -> 0.034811254 | M50: [ Hd_Mixed + Hd_Residential ] | S50: High Density Developed | T50: =+T27+T30 -> 965.4321 | U50: =+T50/T$51 -> 0.034811254 | V50: [ Hd_Mixed + Hd_Residential ]
B51: Total | C51: =+C48+C49+C50 -> 27733.333 | D51: =+C51/C$51 -> 1 | E51: [ All "Developed" land use categories ] | J51: Total | K51: =+K48+K49+K50 -> 27733.333 | L51: =+K51/K$51 -> 1 | M51: [ All "Developed" land use categories ] | S51: Total | T51: =+T48+T49+T50 -> 27733.333 | U51: =+T51/T$51 -> 1 | V51: [ All "Developed" land use categories ]
A54: Step 5. Calculate the portion of the Stream Bank Sediment Load resulting from "Developed" Lands | I54: Step 5. Calculate the portion of the Stream Bank Total Nitrogen (TN) Load resulting from "Developed" Lands | R54: Step 5. Calculate the portion of the Stream Bank Total Phosphorus (TP) Load resulting from "Developed" Lands
B55: This is A) 75% of the Stream Bank Sediment Load times the percent of developed lands in the watershed | J55: This is A) 75% of the Stream Bank Total Nitrogen Load times the percent of developed lands in the watershed | S55: This is A) 75% of the Stream Bank Total Phosphorus Load times the percent of developed lands in the
B56: plus B) 25% of the Stream Bank Sediment Load: | J56: plus B) 25% of the Stream Bank Total Nitrogen Load: | S56: watershed plus B) 25% of the Stream Bank Total Phosphorus Load:
B58: Stream Bank Sediment Load | C58: =C37 -> 53400140 | D58: pounds | E58: from Step 2 | J58: Stream Bank TN Load | K58: =K37 -> 33246.99 | L58: pounds | M58: from Step 2 | S58: Stream Bank TP Load | T58: =T37 -> 13291.74 | U58: pounds | V58: from Step 2
B59: Total Developed Acres | C59: =+C51 -> 27733.333 | D59: acres | E59: from Step 4 | J59: Total Developed Acres | K59: =+K51 -> 27733.333 | L59: acres | M59: from Step 4 | S59: Total Developed Acres | T59: =+T51 -> 27733.333 | U59: acres | V59: from Step 4
...

Sheet Urban BMPs
A1: Urban BMP Load Reduction Calculation Table
A2: INSTRUCTIONS: Each row in the table below can represent either different areas of land use/cover within a single planning area (e.g., municipality), or different BMP drainage areas within a given planning area.
A3: If an individual planning area has multiple "developed land" types, each type can be represented in separate rows, with each row having the same "Project Name". If it is assumed that the planning area is being treated by one BMP system, then the "Treatment Depth" should be the same for each row.
A4: Similarly, a given planning area can have multiple "BMP drainage areas" (i.e., areas treated by different BMP systems). If a BMP drainage area has multiple "developed land" types, separate "land use areas" can be represented on separate rows, with each row having the same "Project Name". Also, in the case of "RR" and "ST" BMP types, the treatment depth should be the same for any row associated with the same Project Name.
A5: If runoff from a land use/cover type with NO impervious cover (e.g., Cropland) is treated by a BMP system (either existing or proposed), use the Manual Override (column R) to type in the treatment depth instead of column Q as would normally be done.
A6: Examples of various options for characterizing different types of project areas are provided in the "Example" spreadsheet that is also available for downloading from the Model My Watershed site.
A8: Project_name | B8: BMP_name | C8: BMP_class | D8: Existing? | E8: yearInstalled | I8: drainageLandCoverClass | J8: drainageArea_ac | K8: treatmentDepth_in | L8: lengthTreatedStream_ft | M8: lengthTreatedRoad_ft | N8: impervArea_ac | Q8: treatmentDepthNormalized_inPerImpervAc | R8: treatmentDepthNormalizedManual_inPerImpervAc | S8: treatmentDepthNormalizedEffective_inPerImpervAc | T8: impervFraction_percent | U8: TSS_Load_lbPerY | V8: TP_Load_lbPerY | W8: TN_Load_lbPerY | X8: TSS_ReductionEfficiency_percent | Y8: TP_ReductionEfficiency_percent | Z8: TN_ReductionEfficiency_percent | AA8: TSS_Reduction_lbPerY | AB8: TSS_Reduction_tonPerY | AC8: TP_Reduction_lbPerY | AD8: TN_Reduction_lbPerY
A9: Project Name | B9: BMP Name | C9: BMP Type | D9: Existing or Proposed | E9: Year Installed | F9: BMP Surface Area (Square Feet) | G9: BMP Surface Area (Acres) | H9: Water Volume Captured by BMP (Cubic Feet) | I9: MapShed Land Cover of Drainage Area | J9: Drainage Area Treated by BMP (Acres) | K9: Treatment Depth (inches of rainfall) | L9: Stream Restoration length (feet) - Qualified projects only | M9: Street Sweeping* Road Length Swept (ft) - Qualified projects only | N9: Impervious Area (ac) | O9: BMP Loading Ratio1 (Impervious Area / BMP Surface Area) | P9: BMP Loading Ratio2 (BMP Water Vol / Runoff Vol from 2.5" Rain ) | Q9: Treatment Depth (in/imp. ac) | R9: Treatment Depth (in/ac) for Manual Override - use if no impervious area | S9: Effective Treatment Depth (in/imp. ac) | T9: Impervious Surface (%) | U9: TSS Load (lbs/yr) | V9: TP Load (lbs/yr) | W9: TN Load (lbs/yr) | X9: TSS Reduction (%) | Y9: TP Reduction (%) | Z9: TN Reduction (%) | AA9: TSS Reduction (lbs/yr) | AB9: TSS Reduction (tons/yr) | AC9: TP Reduction (lbs/yr) | AD9: TN Reduction (lbs/yr)
A10: Project_name | B10: BMP_name | C10: BMP_type | D10: Existing? | E10: YearInstalled | F10: SquareFeet | G10: Acres | H10: CubicFeet | I10: drainageLandCoverClass | J10: drainageArea_ac | K10: treatmentDepth_in | L10: lengthTreatedStream_ft | M10: lengthTreatedRoad_ft2 | N10: impervArea_ac | O10: LoadRatio1 | P10: LoadRatio2 | Q10: treatmentDepthNormalized_inPerImpervAc | R10: treatmentDepthNormalizedManual_inPerImpervAc | S10: treatmentDepthNormalizedEffective_inPerImpervAc | T10: impervFraction_percent | U10: TSS_Load_lbPerY | V10: TP_Load_lbPerY | W10: TN_Load_lbPerY | X10: TSS_ReductionEfficiency_percent | Y10: TP_ReductionEfficiency_percent | Z10: TN_ReductionEfficiency_percent | AA10: TSS_Reduction_lbPerY | AB10: TSS_Reduction_tonPerY | AC10: TP_Reduction_lbPerY | AD10: TN_Reduction_lbPerY
